<?xml version='1.0'?>

<robot name="myrobot" xmlns:xacro="http://www.ros.org/wiki/xacro">
  
  <xacro:include filename="$(find karbot_description)/urdf/materials.xacro" />
  <xacro:include filename="$(find karbot_description)/urdf/karbot.gazebo" />
  <xacro:include filename="$(find karbot_description)/urdf/macros.xacro" />

  <link name="base_link">
    <visual>
      <geometry>
        <cylinder length="0.176" radius="0.295051"/>
      </geometry>
      <origin rpy="0 0 0" xyz="0 0 0.153988"/>
    </visual>

    <collision name= "collison_base_link">
      <origin rpy="0 0 0" xyz="0 0 0.153988"/>
      <geometry>
        <cylinder length="0.176" radius="0.295051"/>
      </geometry>
    </collision>
    <inertial>
      <mass value="1"/>
      <origin rpy="0 0 0" xyz="0 0 0.153988"/>
      <xacro:cylinder_inertia mass="1" r="0.295051" l="0.176" />
    </inertial>
  </link>

  <!--link name="upper_chassis">
    <visual>
      <geometry>
        <cylinder length="0.601382" radius="0.295051"/>
      </geometry>
      <origin rpy="0 0 0" xyz="0 0 0"/>
    </visual>

    <collision name = "collision_upper_chassis">
      <geometry>
        <cylinder length="0.601382" radius="0.295051"/>
      </geometry>
    </collision>
    <inertial>
      <origin xyz="0 0 0.602679"/>	
      <mass value="1"/>
      <xacro:cylinder_inertia mass="1" r="0.295051" l="0.601382" />
    </inertial>
  </link>

  <joint name="upper_chassis_hinge" type="fixed">
    <parent link="base_link"/>
    <child link="upper_chassis"/>
    <origin rpy="0 0 0" xyz="0 0 0.602679"/>
  </joint-->

  <link name="front_caster">
    <visual>
      <geometry>
        <sphere radius="0.025925"/>
      </geometry>
      <origin rpy="0 0 0" xyz="0 0 0"/>
    </visual>

    <collision>
      <geometry>
        <sphere radius="0.025925"/>
      </geometry>
      <surface>
        <friction>
          <ode>
            <mu>0</mu>
            <mu2>0</mu2>
            <slip1>1.0</slip1>
            <slip2>1.0</slip2>
          </ode>
        </friction>
      </surface>
    </collision>
    <inertial>
      <mass value="0.2"/>
      <inertia ixx="0.004481" ixy="0.0" ixz="0.0" iyy="0.004481" iyz="0.0" izz="0.004481"/>
    </inertial>
  </link>

  <joint name="front_caster_hinge" type="fixed">
    <parent link="base_link"/>
    <child link="front_caster"/>
    <origin xyz="0.220488 0 0.025"/>
  </joint>

  <link name="rear_caster">
    <visual>
      <geometry>
        <sphere radius="0.026925"/>
      </geometry>
      <origin rpy="0 0 0" xyz="0 0 0"/>
    </visual>

    <collision>
      <geometry>
        <sphere radius="0.025925"/>
      </geometry>
      <surface>
        <friction>
          <ode>
            <mu>0</mu>
            <mu2>0</mu2>
            <slip1>1.0</slip1>
            <slip2>1.0</slip2>
          </ode>
        </friction>
      </surface>
    </collision>
    <inertial>
      <mass value="0.2"/>
      <inertia ixx="0.001" ixy="0.0" ixz="0.0" iyy="0.001" iyz="0.0" izz="0.001"/>
    </inertial>
  </link>

  <joint name="rear_caster_hinge" type="fixed">
    <parent link="base_link"/>
    <child link="rear_caster"/>
    <origin xyz="-0.220488 0 0.026925"/>
  </joint>

  <link name="left_wheel">
    <visual>
      <geometry>
        <cylinder length=".025400" radius="0.102173"/>
      </geometry>
      <origin rpy="0 1.5707 1.5707" xyz="0 0 0"/>
    </visual>

    <collision>
      <origin rpy="0 1.5707 1.5707" xyz="0 0 0"/>
      <geometry>
        <cylinder length=".025400" radius="0.102173"/>
      </geometry>
    </collision>
    <inertial>
      <mass value="0.3"/>
      <xacro:cylinder_inertia mass="0.3" r="0.102173" l="0.0254" />
    </inertial>
  </link>

  <joint name="left_wheel_hinge" type="continuous">
    <parent link="base_link"/>
    <child link="left_wheel"/>
     <origin rpy="0 0 0" xyz="0 0.213950 0.102173"/>
     <axis xyz="0 1 0"/>
     <limit effort="10000" velocity="1000"/>
     <joint_properties damping="1.0" friction="1.0"/>
  </joint>

  <link name="right_wheel">
    <visual>
      <geometry>
        <cylinder length=".025400" radius="0.102173"/>
      </geometry>
      <origin rpy="0 1.5707 1.5707" xyz="0 0 0"/>
    </visual>

    <collision>
      <origin rpy="0 1.5707 1.5707" xyz="0 0 0"/>
      <geometry>
        <cylinder length=".025400" radius="0.102173"/>
      </geometry>
    </collision>
    <inertial>
      <mass value="0.3"/>
      <xacro:cylinder_inertia mass="0.3" r="0.102173" l="0.0254" />
    </inertial>
  </link>

  <joint name="right_wheel_hinge" type="continuous">
    <parent link="base_link"/>
    <child link="right_wheel"/>
     <origin rpy="0 0 0" xyz="0 -0.213950 0.102173"/>
    <axis xyz="0 1 0"/>
    <limit effort="10000" velocity="1000"/>
    <joint_properties damping="1.0" friction="1.0"/>
  </joint>

  <link name="lidar">
    <visual>
      <geometry>
        <cylinder length="0.055" radius="0.0508"/>
      </geometry>
      <origin rpy="0 0 0" xyz="0 0 0"/>
    </visual>

    <collision>
      <geometry>
        <cylinder length="0.055" radius="0.0508"/>
      </geometry>
    </collision>
    <inertial>
      <mass value="0.2"/>
      <xacro:cylinder_inertia mass="0.2" r="0.0508" l="0.055" />
    </inertial>
  </link>

  <joint name="lidar_hinge" type="fixed">
    <parent link="base_link"/>
    <child link="lidar"/>
    <origin xyz="0 0 0.269488"/>
  </joint>

</robot>

